<?xml version="1.0"?>
<robot name="ur5e_ik" version="1.0">
  <link name="ikv_base_link"/>
  <link name="ikv_base_link_inertia">
    <inertial>
      <origin xyz="0.0 0.0 0.0" rpy="0.0 0.0 0.0"/>
      <mass value="4.0"/>
      <inertia ixx="0.00443333156" ixy="0.0" ixz="0.0" iyy="0.00443333156" iyz="0.0" izz="0.0072"/>
    </inertial>
    <visual>
      <origin xyz="0.0 0.0 0.0" rpy="0.0 0.0 3.141592653589793"/>
      <geometry>
        <mesh filename="package://ur_description/meshes/ur5e/visual/base.dae"/>
      </geometry>
      <material name="LightGrey">
        <color rgba="0.7 0.7 0.7 1.0"/>
      </material>
    </visual>
    <collision>
      <origin xyz="0.0 0.0 0.0" rpy="0.0 0.0 3.141592653589793"/>
      <geometry>
        <mesh filename="package://ur_description/meshes/ur5e/collision/base.stl"/>
      </geometry>
    </collision>
  </link>
  <link name="ikv_shoulder_link">
    <inertial>
      <origin xyz="0.0 0.0 0.0" rpy="0.0 0.0 0.0"/>
      <mass value="3.7"/>
      <inertia ixx="0.010267495893" ixy="0.0" ixz="0.0" iyy="0.010267495893" iyz="0.0" izz="0.00666"/>
    </inertial>
    <visual>
      <origin xyz="0.0 0.0 0.0" rpy="0.0 0.0 3.141592653589793"/>
      <geometry>
        <mesh filename="package://ur_description/meshes/ur5e/visual/shoulder.dae"/>
      </geometry>
      <material name="LightGrey">
        <color rgba="0.7 0.7 0.7 1.0"/>
      </material>
    </visual>
    <collision>
      <origin xyz="0.0 0.0 0.0" rpy="0.0 0.0 3.141592653589793"/>
      <geometry>
        <mesh filename="package://ur_description/meshes/ur5e/collision/shoulder.stl"/>
      </geometry>
    </collision>
  </link>
  <link name="ikv_upper_arm_link">
    <inertial>
      <origin xyz="-0.2125 0.0 0.138" rpy="0.0 1.5707963267948966 0.0"/>
      <mass value="8.393"/>
      <inertia ixx="0.1338857818623325" ixy="0.0" ixz="0.0" iyy="0.1338857818623325" iyz="0.0" izz="0.0151074"/>
    </inertial>
    <visual>
      <origin xyz="0.0 0.0 0.138" rpy="1.5707963267948966 0.0 -1.5707963267948966"/>
      <geometry>
        <mesh filename="package://ur_description/meshes/ur5e/visual/upperarm.dae"/>
      </geometry>
      <material name="LightGrey">
        <color rgba="0.7 0.7 0.7 1.0"/>
      </material>
    </visual>
    <collision>
      <origin xyz="0.0 0.0 0.138" rpy="1.5707963267948966 0.0 -1.5707963267948966"/>
      <geometry>
        <mesh filename="package://ur_description/meshes/ur5e/collision/upperarm.stl"/>
      </geometry>
    </collision>
  </link>
  <link name="ikv_forearm_link">
    <inertial>
      <origin xyz="-0.1961 0.0 0.007" rpy="0.0 1.5707963267948966 0.0"/>
      <mass value="2.275"/>
      <inertia ixx="0.031209355099586295" ixy="0.0" ixz="0.0" iyy="0.031209355099586295" iyz="0.0" izz="0.004095"/>
    </inertial>
    <visual>
      <origin xyz="0.0 0.0 0.007" rpy="1.5707963267948966 0.0 -1.5707963267948966"/>
      <geometry>
        <mesh filename="package://ur_description/meshes/ur5e/visual/forearm.dae"/>
      </geometry>
      <material name="LightGrey">
        <color rgba="0.7 0.7 0.7 1.0"/>
      </material>
    </visual>
    <collision>
      <origin xyz="0.0 0.0 0.007" rpy="1.5707963267948966 0.0 -1.5707963267948966"/>
      <geometry>
        <mesh filename="package://ur_description/meshes/ur5e/collision/forearm.stl"/>
      </geometry>
    </collision>
  </link>
  <link name="ikv_wrist_1_link">
    <inertial>
      <origin xyz="0.0 0.0 0.0" rpy="0.0 0.0 0.0"/>
      <mass value="1.219"/>
      <inertia ixx="0.0025598989760400002" ixy="0.0" ixz="0.0" iyy="0.0025598989760400002" iyz="0.0" izz="0.0021942"/>
    </inertial>
    <visual>
      <origin xyz="0.0 0.0 -0.127" rpy="1.5707963267948966 0.0 0.0"/>
      <geometry>
        <mesh filename="package://ur_description/meshes/ur5e/visual/wrist1.dae"/>
      </geometry>
      <material name="LightGrey">
        <color rgba="0.7 0.7 0.7 1.0"/>
      </material>
    </visual>
    <collision>
      <origin xyz="0.0 0.0 -0.127" rpy="1.5707963267948966 0.0 0.0"/>
      <geometry>
        <mesh filename="package://ur_description/meshes/ur5e/collision/wrist1.stl"/>
      </geometry>
    </collision>
  </link>
  <link name="ikv_wrist_2_link">
    <inertial>
      <origin xyz="0.0 0.0 0.0" rpy="0.0 0.0 0.0"/>
      <mass value="1.219"/>
      <inertia ixx="0.0025598989760400002" ixy="0.0" ixz="0.0" iyy="0.0025598989760400002" iyz="0.0" izz="0.0021942"/>
    </inertial>
    <visual>
      <origin xyz="0.0 0.0 -0.0997" rpy="0.0 0.0 0.0"/>
      <geometry>
        <mesh filename="package://ur_description/meshes/ur5e/visual/wrist2.dae"/>
      </geometry>
      <material name="LightGrey">
        <color rgba="0.7 0.7 0.7 1.0"/>
      </material>
    </visual>
    <collision>
      <origin xyz="0.0 0.0 -0.0997" rpy="0.0 0.0 0.0"/>
      <geometry>
        <mesh filename="package://ur_description/meshes/ur5e/collision/wrist2.stl"/>
      </geometry>
    </collision>
  </link>
  <link name="ikv_wrist_3_link">
    <inertial>
      <origin xyz="0.0 0.0 -0.0229" rpy="0.0 0.0 0.0"/>
      <mass value="0.1879"/>
      <inertia ixx="9.890410052167731e-05" ixy="0.0" ixz="0.0" iyy="9.890410052167731e-05" iyz="0.0" izz="0.0001321171875"/>
    </inertial>
    <visual>
      <origin xyz="0.0 0.0 -0.0989" rpy="1.5707963267948966 0.0 0.0"/>
      <geometry>
        <mesh filename="package://ur_description/meshes/ur5e/visual/wrist3.dae"/>
      </geometry>
      <material name="LightGrey">
        <color rgba="0.7 0.7 0.7 1.0"/>
      </material>
    </visual>
    <collision>
      <origin xyz="0.0 0.0 -0.0989" rpy="1.5707963267948966 0.0 0.0"/>
      <geometry>
        <mesh filename="package://ur_description/meshes/ur5e/collision/wrist3.stl"/>
      </geometry>
    </collision>
  </link>
  <joint name="ikv_base_link-base_link_inertia" type="fixed">
    <origin xyz="0.0 0.0 0.0" rpy="0.0 0.0 3.141592653589793"/>
    <parent link="ikv_base_link"/>
    <child link="ikv_base_link_inertia"/>
  </joint>
  <joint name="ikv_shoulder_pan_joint" type="revolute">
    <origin xyz="0.0 0.0 0.1625535101374433" rpy="0.0 0.0 -4.287074301112526e-08"/>
    <axis xyz="0.0 0.0 1.0"/>
    <parent link="ikv_base_link_inertia"/>
    <child link="ikv_shoulder_link"/>
    <limit effort="150.0" lower="-6.283185307179586" upper="6.283185307179586" velocity="3.141592653589793"/>
    <dynamics damping="0.0" friction="0.0"/>
    <safety_controller k_velocity="0.0" k_position="20.0" soft_lower_limit="-6.133185307179586" soft_upper_limit="6.133185307179586"/>
  </joint>
  <joint name="ikv_shoulder_lift_joint" type="revolute">
    <origin xyz="-1.994606673231543e-05 0.0 0.0" rpy="1.570819544642547 0.0 -2.012967029370527e-06"/>
    <axis xyz="0.0 0.0 1.0"/>
    <parent link="ikv_shoulder_link"/>
    <child link="ikv_upper_arm_link"/>
    <limit effort="150.0" lower="-6.283185307179586" upper="6.283185307179586" velocity="3.141592653589793"/>
    <dynamics damping="0.0" friction="0.0"/>
    <safety_controller k_velocity="0.0" k_position="20.0" soft_lower_limit="-6.133185307179586" soft_upper_limit="6.133185307179586"/>
  </joint>
  <joint name="ikv_elbow_joint" type="revolute">
    <origin xyz="-0.425098252441738 0.0 0.0" rpy="3.141502314133674 -3.140574463962915 -3.141590285679638"/>
    <axis xyz="0.0 0.0 1.0"/>
    <parent link="ikv_upper_arm_link"/>
    <child link="ikv_forearm_link"/>
    <limit effort="150.0" lower="-3.141592653589793" upper="3.141592653589793" velocity="3.141592653589793"/>
    <dynamics damping="0.0" friction="0.0"/>
    <safety_controller k_velocity="0.0" k_position="20.0" soft_lower_limit="-2.991592653589793" soft_upper_limit="2.991592653589793"/>
  </joint>
  <joint name="ikv_wrist_1_joint" type="revolute">
    <origin xyz="-0.3922143575700871 -0.0006210476473596001 0.1336052586854132" rpy="0.004648343788642296 0.0006025309972401929 -7.383257797914409e-07"/>
    <axis xyz="0.0 0.0 1.0"/>
    <parent link="ikv_forearm_link"/>
    <child link="ikv_wrist_1_link"/>
    <limit effort="28.0" lower="-6.283185307179586" upper="6.283185307179586" velocity="3.141592653589793"/>
    <dynamics damping="0.0" friction="0.0"/>
    <safety_controller k_velocity="0.0" k_position="20.0" soft_lower_limit="-6.133185307179586" soft_upper_limit="6.133185307179586"/>
  </joint>
  <joint name="ikv_wrist_2_joint" type="revolute">
    <origin xyz="6.309743493552485e-05 -0.09976189546848034 9.095013053426803e-05" rpy="1.569884655009697 0.0 -2.078516231698857e-07"/>
    <axis xyz="0.0 0.0 1.0"/>
    <parent link="ikv_wrist_1_link"/>
    <child link="ikv_wrist_2_link"/>
    <limit effort="28.0" lower="-6.283185307179586" upper="6.283185307179586" velocity="3.141592653589793"/>
    <dynamics damping="0.0" friction="0.0"/>
    <safety_controller k_velocity="0.0" k_position="20.0" soft_lower_limit="-6.133185307179586" soft_upper_limit="6.133185307179586"/>
  </joint>
  <joint name="ikv_wrist_3_joint" type="revolute">
    <origin xyz="1.877592835709357e-05 0.09973050279255603 7.91315518559599e-06" rpy="1.570875672180184 3.141592653589793 3.141592333753604"/>
    <axis xyz="0.0 0.0 1.0"/>
    <parent link="ikv_wrist_2_link"/>
    <child link="ikv_wrist_3_link"/>
    <limit effort="28.0" lower="-6.283185307179586" upper="6.283185307179586" velocity="3.141592653589793"/>
    <dynamics damping="0.0" friction="0.0"/>
    <safety_controller k_velocity="0.0" k_position="20.0" soft_lower_limit="-6.133185307179586" soft_upper_limit="6.133185307179586"/>
  </joint>
  <link name="ikv_base"/>
  <joint name="ikv_base_link-base_fixed_joint" type="fixed">
    <origin xyz="0.0 0.0 0.0" rpy="0.0 0.0 3.141592653589793"/>
    <parent link="ikv_base_link"/>
    <child link="ikv_base"/>
  </joint>
  <link name="ikv_flange"/>
  <joint name="ikv_wrist_3-flange" type="fixed">
    <origin xyz="0.0 0.0 0.0" rpy="0.0 -1.5707963267948966 -1.5707963267948966"/>
    <parent link="ikv_wrist_3_link"/>
    <child link="ikv_flange"/>
  </joint>
  <link name="ikv_tool0"/>
  <joint name="ikv_flange-tool0" type="fixed">
    <origin xyz="0.0 0.0 0.0" rpy="1.5707963267948966 0.0 1.5707963267948966"/>
    <parent link="ikv_flange"/>
    <child link="ikv_tool0"/>
  </joint>
  <link name="ikv_gripper"/>
  <joint name="ikv_tool0-gripper" type="fixed">
    <origin xyz="0.0 0.0 0.14" rpy="0.0 0.0 0.0"/>
    <parent link="ikv_tool0"/>
    <child link="ikv_gripper"/>
  </joint>
</robot>
